Workbook

Sheet أرصدة المخزن
A2: رصيد اول المدة مخزن أدارة الامن والتشغيل - كمبوند ستون ريزيدنس بدايتا من 01 / 01 / 2026
A3: الكود | B3: المخزن | C3: اسم الصنف | D3: الوحدة | E3: رصيد اول المدة | F3: إضافة | G3: صرف | H3: الرصيــــــــــــــــــد | I3: =TODAY() | J3: =+I3-60 | M3: قائمة الأصناف النشطة | O3: قائمة الأقسام المعتمدة
A4: 10010001 | B4: أدوات كهربائية | C4: لقمة بريزة | D4: عدد | E4: 470 | F4: =SUMIFS(الاضافة!$G$7:$G$60000,الاضافة!$H$7:$H$60000,"*اضاف*",الاضافة!$E$7:$E$60000,'أرصدة المخزن'!C4) | G4: =SUMIFS(الصرف!$H$7:$H$60000,الصرف!$F$7:$F$60000,'أرصدة المخزن'!C4) | H4: =E4+F4-G4 | I4: =SUMIFS(الاضافة!$G$7:$G$50033,الاضافة!$H$7:$H$50033,"اضافة",الاضافة!$E$7:$E$50033,'أرصدة المخزن'!F4) | J4: =SUMIFS(الصرف!$H$7:$H$48386,الصرف!$F$7:$F$48386,'أرصدة المخزن'!F4) | M4: Astral pool 200m 220v 2HPمضخة استرال | O4: أدوات كهربائية
A5: 10010002 | B5: أدوات كهربائية | C5: مفتاح احادي 20 امبير | D5: عدد | E5: 0 | F5: =SUMIFS(الاضافة!$G$7:$G$60000,الاضافة!$H$7:$H$60000,"*اضاف*",الاضافة!$E$7:$E$60000,'أرصدة المخزن'!C5) | G5: =SUMIFS(الصرف!$H$7:$H$60000,الصرف!$F$7:$F$60000,'أرصدة المخزن'!C5) | H5: =E5+F5-G5 | M5: DW 40 | O5: أدوات سباكة
A6: 10010003 | B6: أدوات كهربائية | C6: سلكتور | D6: عدد | E6: 0 | F6: =SUMIFS(الاضافة!$G$7:$G$60000,الاضافة!$H$7:$H$60000,"*اضاف*",الاضافة!$E$7:$E$60000,'أرصدة المخزن'!C6) | G6: =SUMIFS(الصرف!$H$7:$H$60000,الصرف!$F$7:$F$60000,'أرصدة المخزن'!C6) | H6: =E6+F6-G6 | M6: PVC | O6: أدوات خامات الري
A7: 10010004 | B7: أدوات كهربائية | C7: سدادة | D7: عدد | E7: 49 | F7: =SUMIFS(الاضافة!$G$7:$G$60000,الاضافة!$H$7:$H$60000,"*اضاف*",الاضافة!$E$7:$E$60000,'أرصدة المخزن'!C7) | G7: =SUMIFS(الصرف!$H$7:$H$60000,الصرف!$F$7:$F$60000,'أرصدة المخزن'!C7) | H7: =E7+F7-G7 | M7: Power Sapply | O7: حمامات سباحة
A8: 10010005 | B8: أدوات كهربائية | C8: لقمة جرس | D8: عدد | E8: 68 | F8: =SUMIFS(الاضافة!$G$7:$G$60000,الاضافة!$H$7:$H$60000,"*اضاف*",الاضافة!$E$7:$E$60000,'أرصدة المخزن'!C8) | G8: =SUMIFS(الصرف!$H$7:$H$60000,الصرف!$F$7:$F$60000,'أرصدة المخزن'!C8) | H8: =E8+F8-G8 | M8: UNI-BEX منظم صوت+ميكروفون | O8: مستلزمات نظافة
A9: 10010006 | B9: أدوات كهربائية | C9: مفتاح احادي 16 امبير | D9: عدد | E9: 0 | F9: =SUMIFS(الاضافة!$G$7:$G$60000,الاضافة!$H$7:$H$60000,"*اضاف*",الاضافة!$E$7:$E$60000,'أرصدة المخزن'!C9) | G9: =SUMIFS(الصرف!$H$7:$H$60000,الصرف!$F$7:$F$60000,'أرصدة المخزن'!C9) | H9: =E9+F9-G9 | M9: z باكتة | O9: أدوات نقاشة
A10: 10010007 | B10: أدوات كهربائية | C10: مفتاح شنبدر 25 امبير | D10: عدد | E10: 0 | F10: =SUMIFS(الاضافة!$G$7:$G$60000,الاضافة!$H$7:$H$60000,"*اضاف*",الاضافة!$E$7:$E$60000,'أرصدة المخزن'!C10) | G10: =SUMIFS(الصرف!$H$7:$H$60000,الصرف!$F$7:$F$60000,'أرصدة المخزن'!C10) | H10: =E10+F10-G10 | M10: أسطوانات فلترة | O10: أدوات وخامات نجارة
A11: 10010008 | B11: أدوات كهربائية | C11: مفتاح احادي 32 امبير | D11: عدد | E11: 0 | F11: =SUMIFS(الاضافة!$G$7:$G$60000,الاضافة!$H$7:$H$60000,"*اضاف*",الاضافة!$E$7:$E$60000,'أرصدة المخزن'!C11) | G11: =SUMIFS(الصرف!$H$7:$H$60000,الصرف!$F$7:$F$60000,'أرصدة المخزن'!C11) | H11: =E11+F11-G11 | M11: أسطوانة رخام الماظة | O11: أدوات عامة
A12: 10010009 | B12: أدوات كهربائية | C12: مفتاح احادي 10 امبير | D12: عدد | E12: 0 | F12: =SUMIFS(الاضافة!$G$7:$G$60000,الاضافة!$H$7:$H$60000,"*اضاف*",الاضافة!$E$7:$E$60000,'أرصدة المخزن'!C12) | G12: =SUMIFS(الصرف!$H$7:$H$60000,الصرف!$F$7:$F$60000,'أرصدة المخزن'!C12) | H12: =E12+F12-G12 | M12: أسطوانة غاز ( امبوبة ) | O12: أدوات سيكوريت
A13: 10010010 | B13: أدوات كهربائية | C13: مفتاح بوش بوتن | D13: عدد | E13: 0 | F13: =SUMIFS(الاضافة!$G$7:$G$60000,الاضافة!$H$7:$H$60000,"*اضاف*",الاضافة!$E$7:$E$60000,'أرصدة المخزن'!C13) | G13: =SUMIFS(الصرف!$H$7:$H$60000,الصرف!$F$7:$F$60000,'أرصدة المخزن'!C13) | H13: =E13+F13-G13 | M13: أسطوانة قطعية حدادي | O13: أدوات الوميتال
A14: 10010011 | B14: أدوات كهربائية | C14: هيربشن 250 امبير | D14: عدد | E14: 44 | F14: =SUMIFS(الاضافة!$G$7:$G$60000,الاضافة!$H$7:$H$60000,"*اضاف*",الاضافة!$E$7:$E$60000,'أرصدة المخزن'!C14) | G14: =SUMIFS(الصرف!$H$7:$H$60000,الصرف!$F$7:$F$60000,'أرصدة المخزن'!C14) | H14: =E14+F14-G14 | M14: أكسيد احمر 250 جرام | O14: أدوات مكاتب
A15: 10010012 | B15: أدوات كهربائية | C15: مفتاح ثلاثي شنايدر C25 | D15: عدد | E15: 0 | F15: =SUMIFS(الاضافة!$G$7:$G$60000,الاضافة!$H$7:$H$60000,"*اضاف*",الاضافة!$E$7:$E$60000,'أرصدة المخزن'!C15) | G15: =SUMIFS(الصرف!$H$7:$H$60000,الصرف!$F$7:$F$60000,'أرصدة المخزن'!C15) | H15: =E15+F15-G15 | M15: أكسيد اسود 250 جرام | O15: أدوات ميكانيكا
A16: 10010013 | B16: أدوات كهربائية | C16: شاسية بتشينو | D16: عدد | E16: 29 | F16: =SUMIFS(الاضافة!$G$7:$G$60000,الاضافة!$H$7:$H$60000,"*اضاف*",الاضافة!$E$7:$E$60000,'أرصدة المخزن'!C16) | G16: =SUMIFS(الصرف!$H$7:$H$60000,الصرف!$F$7:$F$60000,'أرصدة المخزن'!C16) | H16: =E16+F16-G16 | M16: أكسيد اصفر 250 جرام | O16: أدوات الأمن وكاميرات المراقبة
... A25: 10010022 | B25: أدوات كهربائية | C25: مفتاح تكييف 32 امبير | D25: عدد | E25: 0 | F25: =SUMIFS(الاضافة!$G$7:$G$60000,الاضافة!$H$7:$H$60000,"*اضاف*",الاضافة!$E$7:$E$60000,'أرصدة المخزن'!C25) | G25: =SUMIFS(الصرف!$H$7:$H$60000,الصرف!$F$7:$F$60000,'أرصدة المخزن'!C25) | H25: =E25+F25-G25 | M25: ابليك UP&down | O25: مكتب الإدارة
A26: 10010023 | B26: أدوات كهربائية | C26: بريزة خارجية | D26: عدد | E26: 0 | F26: =SUMIFS(الاضافة!$G$7:$G$60000,الاضافة!$H$7:$H$60000,"*اضاف*",الاضافة!$E$7:$E$60000,'أرصدة المخزن'!C26) | G26: =SUMIFS(الصرف!$H$7:$H$60000,الصرف!$F$7:$F$60000,'أرصدة المخزن'!C26) | H26: =E26+F26-G26 | M26: ابليك سور الكمبوبد
A27: 10010024 | B27: أدوات كهربائية | C27: هيربشن 160 امبير abb | D27: عدد | E27: 49 | F27: =SUMIFS(الاضافة!$G$7:$G$60000,الاضافة!$H$7:$H$60000,"*اضاف*",الاضافة!$E$7:$E$60000,'أرصدة المخزن'!C27) | G27: =SUMIFS(الصرف!$H$7:$H$60000,الصرف!$F$7:$F$60000,'أرصدة المخزن'!C27) | H27: =E27+F27-G27 | M27: ابليك ورم 10 وات
A28: 10010025 | B28: أدوات كهربائية | C28: غطاء مفتاح ثلاثي | D28: عدد | E28: 15 | F28: =SUMIFS(الاضافة!$G$7:$G$60000,الاضافة!$H$7:$H$60000,"*اضاف*",الاضافة!$E$7:$E$60000,'أرصدة المخزن'!C28) | G28: =SUMIFS(الصرف!$H$7:$H$60000,الصرف!$F$7:$F$60000,'أرصدة المخزن'!C28) | H28: =E28+F28-G28 | M28: ادي بوند 1 لتر
A29: 10010026 | B29: أدوات كهربائية | C29: هيربشن 400 امبير | D29: عدد | E29: 10 | F29: =SUMIFS(الاضافة!$G$7:$G$60000,الاضافة!$H$7:$H$60000,"*اضاف*",الاضافة!$E$7:$E$60000,'أرصدة المخزن'!C29) | G29: =SUMIFS(الصرف!$H$7:$H$60000,الصرف!$F$7:$F$60000,'أرصدة المخزن'!C29) | H29: =E29+F29-G29 | M29: اديبوند سائل
A30: 10010027 | B30: أدوات كهربائية | C30: مفتاح ثنائي 63 امبير | D30: عدد | E30: 0 | F30: =SUMIFS(الاضافة!$G$7:$G$60000,الاضافة!$H$7:$H$60000,"*اضاف*",الاضافة!$E$7:$E$60000,'أرصدة المخزن'!C30) | G30: =SUMIFS(الصرف!$H$7:$H$60000,الصرف!$F$7:$F$60000,'أرصدة المخزن'!C30) | H30: =E30+F30-G30 | M30: ازميل 22 م خشابي
A31: 10010028 | B31: أدوات كهربائية | C31: مفتاح 160 امبير | D31: عدد | E31: 1 | F31: =SUMIFS(الاضافة!$G$7:$G$60000,الاضافة!$H$7:$H$60000,"*اضاف*",الاضافة!$E$7:$E$60000,'أرصدة المخزن'!C31) | G31: =SUMIFS(الصرف!$H$7:$H$60000,الصرف!$F$7:$F$60000,'أرصدة المخزن'!C31) | H31: =E31+F31-G31 | M31: اسبراي اكاي
A32: 10010029 | B32: أدوات كهربائية | C32: لقمة بريزة سانشي | D32: لفة | E32: 1 | F32: =SUMIFS(الاضافة!$G$7:$G$60000,الاضافة!$H$7:$H$60000,"*اضاف*",الاضافة!$E$7:$E$60000,'أرصدة المخزن'!C32) | G32: =SUMIFS(الصرف!$H$7:$H$60000,الصرف!$F$7:$F$60000,'أرصدة المخزن'!C32) | H32: =E32+F32-G32 | M32: اسبراي مزيل صداء
A33: 10010030 | B33: أدوات كهربائية | C33: مفتاح قاطع تيار 125 امبير | D33: عدد | E33: 0 | F33: =SUMIFS(الاضافة!$G$7:$G$60000,الاضافة!$H$7:$H$60000,"*اضاف*",الاضافة!$E$7:$E$60000,'أرصدة المخزن'!C33) | G33: =SUMIFS(الصرف!$H$7:$H$60000,الصرف!$F$7:$F$60000,'أرصدة المخزن'!C33) | H33: =E33+F33-G33 | M33: اسبوط انارة داخلية بحيرات
A34: 10010031 | B34: أدوات كهربائية | C34: مفتاح قاطع تيار (بلمبات إشارة) NP تركي | D34: عدد | E34: 0 | F34: =SUMIFS(الاضافة!$G$7:$G$60000,الاضافة!$H$7:$H$60000,"*اضاف*",الاضافة!$E$7:$E$60000,'أرصدة المخزن'!C34) | G34: =SUMIFS(الصرف!$H$7:$H$60000,الصرف!$F$7:$F$60000,'أرصدة المخزن'!C34) | H34: =E34+F34-G34 | M34: اسبوط حربة 12 وات
A35: 10010032 | B35: أدوات كهربائية | C35: مفتاح دفيتير | D35: عدد | E35: 0 | F35: =SUMIFS(الاضافة!$G$7:$G$60000,الاضافة!$H$7:$H$60000,"*اضاف*",الاضافة!$E$7:$E$60000,'أرصدة المخزن'!C35) | G35: =SUMIFS(الصرف!$H$7:$H$60000,الصرف!$F$7:$F$60000,'أرصدة المخزن'!C35) | H35: =E35+F35-G35 | M35: استيكر ZK TECO
A36: 10010033 | B36: أدوات كهربائية | C36: مفتاح دفيتير بتشينو | D36: عدد | E36: 0 | F36: =SUMIFS(الاضافة!$G$7:$G$60000,الاضافة!$H$7:$H$60000,"*اضاف*",الاضافة!$E$7:$E$60000,'أرصدة المخزن'!C36) | G36: =SUMIFS(الصرف!$H$7:$H$60000,الصرف!$F$7:$F$60000,'أرصدة المخزن'!C36) | H36: =E36+F36-G36 | M36: اصدير 750
A37: 10010034 | B37: أدوات كهربائية | C37: بريزة وتر بروف | D37: عدد | E37: 0 | F37: =SUMIFS(الاضافة!$G$7:$G$60000,الاضافة!$H$7:$H$60000,"*اضاف*",الاضافة!$E$7:$E$60000,'أرصدة المخزن'!C37) | G37: =SUMIFS(الصرف!$H$7:$H$60000,الصرف!$F$7:$F$60000,'أرصدة المخزن'!C37) | H37: =E37+F37-G37 | M37: اعواد دكت
... A200: 10010197 | B200: أدوات كهربائية | C200: صباع سيليكون | D200: عدد | E200: 0 | F200: =SUMIFS(الاضافة!$G$7:$G$60000,الاضافة!$H$7:$H$60000,"*اضاف*",الاضافة!$E$7:$E$60000,'أرصدة المخزن'!C200) | G200: =SUMIFS(الصرف!$H$7:$H$60000,الصرف!$F$7:$F$60000,'أرصدة المخزن'!C200) | H200: =E200+F200-G200 | M200: جلبة 75 مم كاسيل
A201: 10010198 | B201: أدوات كهربائية | E201: 0 | F201: =SUMIFS(الاضافة!$G$7:$G$60000,الاضافة!$H$7:$H$60000,"*اضاف*",الاضافة!$E$7:$E$60000,'أرصدة المخزن'!C201) | G201: =SUMIFS(الصرف!$H$7:$H$60000,الصرف!$F$7:$F$60000,'أرصدة المخزن'!C201) | H201: =E201+F201-G201 | M201: جلبة اصلاح 110 كاسيل
A202: 10010199 | B202: أدوات كهربائية | E202: 0 | F202: =SUMIFS(الاضافة!$G$7:$G$60000,الاضافة!$H$7:$H$60000,"*اضاف*",الاضافة!$E$7:$E$60000,'أرصدة المخزن'!C202) | G202: =SUMIFS(الصرف!$H$7:$H$60000,الصرف!$F$7:$F$60000,'أرصدة المخزن'!C202) | H202: =E202+F202-G202 | M202: جلبة اصلاح 160 مم كاسيل
A203: 10010200 | B203: أدوات كهربائية | E203: 0 | F203: =SUMIFS(الاضافة!$G$7:$G$60000,الاضافة!$H$7:$H$60000,"*اضاف*",الاضافة!$E$7:$E$60000,'أرصدة المخزن'!C203) | G203: =SUMIFS(الصرف!$H$7:$H$60000,الصرف!$F$7:$F$60000,'أرصدة المخزن'!C203) | H203: =E203+F203-G203 | M203: جلبة اصلاح 75 مم كاسيل
A204: 10010201 | B204: أدوات كهربائية | E204: 0 | F204: =SUMIFS(الاضافة!$G$7:$G$60000,الاضافة!$H$7:$H$60000,"*اضاف*",الاضافة!$E$7:$E$60000,'أرصدة المخزن'!C204) | G204: =SUMIFS(الصرف!$H$7:$H$60000,الصرف!$F$7:$F$60000,'أرصدة المخزن'!C204) | H204: =E204+F204-G204 | M204: جلبة بسن خارجي 32 ملي بولي
A205: 10010202 | B205: أدوات كهربائية | E205: 0 | F205: =SUMIFS(الاضافة!$G$7:$G$60000,الاضافة!$H$7:$H$60000,"*اضاف*",الاضافة!$E$7:$E$60000,'أرصدة المخزن'!C205) | G205: =SUMIFS(الصرف!$H$7:$H$60000,الصرف!$F$7:$F$60000,'أرصدة المخزن'!C205) | H205: =E205+F205-G205 | M205: جلبة بسن ذكر كومر 63 مم
A206: 10010203 | B206: أدوات كهربائية | E206: 0 | F206: =SUMIFS(الاضافة!$G$7:$G$60000,الاضافة!$H$7:$H$60000,"*اضاف*",الاضافة!$E$7:$E$60000,'أرصدة المخزن'!C206) | G206: =SUMIFS(الصرف!$H$7:$H$60000,الصرف!$F$7:$F$60000,'أرصدة المخزن'!C206) | H206: =E206+F206-G206 | M206: جلبة بولي 25
A207: 10010204 | B207: أدوات كهربائية | E207: 0 | F207: =SUMIFS(الاضافة!$G$7:$G$60000,الاضافة!$H$7:$H$60000,"*اضاف*",الاضافة!$E$7:$E$60000,'أرصدة المخزن'!C207) | G207: =SUMIFS(الصرف!$H$7:$H$60000,الصرف!$F$7:$F$60000,'أرصدة المخزن'!C207) | H207: =E207+F207-G207 | M207: جلبة تطويل 25 مم حديد
A208: 10010205 | B208: أدوات كهربائية | E208: 0 | F208: =SUMIFS(الاضافة!$G$7:$G$60000,الاضافة!$H$7:$H$60000,"*اضاف*",الاضافة!$E$7:$E$60000,'أرصدة المخزن'!C208) | G208: =SUMIFS(الصرف!$H$7:$H$60000,الصرف!$F$7:$F$60000,'أرصدة المخزن'!C208) | H208: =E208+F208-G208 | M208: جلبة خرزان
A209: 10010206 | B209: أدوات كهربائية | E209: 0 | F209: =SUMIFS(الاضافة!$G$7:$G$60000,الاضافة!$H$7:$H$60000,"*اضاف*",الاضافة!$E$7:$E$60000,'أرصدة المخزن'!C209) | G209: =SUMIFS(الصرف!$H$7:$H$60000,الصرف!$F$7:$F$60000,'أرصدة المخزن'!C209) | H209: =E209+F209-G209 | M209: جلبة سن خارجي 32 كومر
A210: 10010207 | B210: أدوات كهربائية | E210: 0 | F210: =SUMIFS(الاضافة!$G$7:$G$60000,الاضافة!$H$7:$H$60000,"*اضاف*",الاضافة!$E$7:$E$60000,'أرصدة المخزن'!C210) | G210: =SUMIFS(الصرف!$H$7:$H$60000,الصرف!$F$7:$F$60000,'أرصدة المخزن'!C210) | H210: =E210+F210-G210 | M210: جلبة سن داخلي 32 كومر
A211: 10010208 | B211: أدوات كهربائية | E211: 0 | F211: =SUMIFS(الاضافة!$G$7:$G$60000,الاضافة!$H$7:$H$60000,"*اضاف*",الاضافة!$E$7:$E$60000,'أرصدة المخزن'!C211) | G211: =SUMIFS(الصرف!$H$7:$H$60000,الصرف!$F$7:$F$60000,'أرصدة المخزن'!C211) | H211: =E211+F211-G211 | M211: جلبة كاسيل 32 مم
...

Sheet الاضافة
B4: 🔍 بحث (اسم أو كود): | D4: الصنف المطابق: | E4: =IF(C4="","",IF(ISNUMBER(C4),IFERROR(INDEX('أرصدة المخزن'!$C$4:$C$60000,MATCH(C4,'أرصدة المخزن'!$A$4:$A$60000,0)),"كود غير موجود"),IFERROR(INDEX('أرصدة المخزن'!$C$4:$C$60000,MATCH("*"&TRIM(C4)&"*",'أرصدة المخزن'!$C$4:$C$60000,0)),"صنف غير موجود"))) | F4: الكود: | G4: =IF(C4="","",IF(ISNUMBER(C4),IFERROR(INDEX('أرصدة المخزن'!$A$4:$A$60000,MATCH(C4,'أرصدة المخزن'!$A$4:$A$60000,0)),""),IFERROR(INDEX('أرصدة المخزن'!$A$4:$A$60000,MATCH("*"&TRIM(C4)&"*",'أرصدة المخزن'!$C$4:$C$60000,0)),""))) | H4: الوحدة: | I4: =IF(C4="","",IF(ISNUMBER(C4),IFERROR(INDEX('أرصدة المخزن'!$D$4:$D$60000,MATCH(C4,'أرصدة المخزن'!$A$4:$A$60000,0)),""),IFERROR(INDEX('أرصدة المخزن'!$D$4:$D$60000,MATCH("*"&TRIM(C4)&"*",'أرصدة المخزن'!$C$4:$C$60000,0)),""))) | J4: الرصيد بالمخزن: | K4: =IF(C4="","",IF(ISNUMBER(C4),IFERROR(INDEX('أرصدة المخزن'!$H$4:$H$60000,MATCH(C4,'أرصدة المخزن'!$A$4:$A$60000,0)),0),IFERROR(INDEX('أرصدة المخزن'!$H$4:$H$60000,MATCH("*"&TRIM(C4)&"*",'أرصدة المخزن'!$C$4:$C$60000,0)),0)))
A6: م | B6: التاريخ | C6: رقم الاذن | D6: كود الصنف | E6: اسم الصنف | F6: الوحدة | G6: الكمية | H6: الإضافة | I6: ملاحظات
A7: 1 | B7: 46023 | C7: 210 | D7: 10040038 | E7: =IFERROR(VLOOKUP(D7,'أرصدة المخزن'!$A:$E,3,0),"") | F7: =IFERROR(VLOOKUP(D7,'أرصدة المخزن'!$A:$H,4,0),"") | G7: 7 | H7: إضافة | I7: وارد من مكتب ادارة الكمبوند
A8: 2 | B8: 46023 | C8: 210 | D8: 10010141 | E8: =IFERROR(VLOOKUP(D8,'أرصدة المخزن'!$A:$E,3,0),"") | F8: =IFERROR(VLOOKUP(D8,'أرصدة المخزن'!$A:$H,4,0),"") | G8: 60 | H8: إضافة | I8: وارد من حفلة الكريسماس بول 1 مجمع خاص بالحفلات والمناسبات
A9: 3 | B9: 46023 | C9: 210 | D9: 10020156 | E9: =IFERROR(VLOOKUP(D9,'أرصدة المخزن'!$A:$E,3,0),"") | F9: =IFERROR(VLOOKUP(D9,'أرصدة المخزن'!$A:$H,4,0),"") | G9: 2 | H9: إضافة
A10: 4 | B10: 46023 | C10: 210 | D10: 10030055 | E10: =IFERROR(VLOOKUP(D10,'أرصدة المخزن'!$A:$E,3,0),"") | F10: =IFERROR(VLOOKUP(D10,'أرصدة المخزن'!$A:$H,4,0),"") | G10: 1 | H10: إضافة
A11: 5 | B11: 46023 | C11: 210 | D11: 10020053 | E11: =IFERROR(VLOOKUP(D11,'أرصدة المخزن'!$A:$E,3,0),"") | F11: =IFERROR(VLOOKUP(D11,'أرصدة المخزن'!$A:$H,4,0),"") | G11: 4 | H11: إضافة
A12: 6 | B12: 46023 | C12: 210 | D12: 10020067 | E12: =IFERROR(VLOOKUP(D12,'أرصدة المخزن'!$A:$E,3,0),"") | F12: =IFERROR(VLOOKUP(D12,'أرصدة المخزن'!$A:$H,4,0),"") | G12: 1 | H12: إضافة
A13: 7 | B13: 46023 | C13: 210 | D13: 10010016 | E13: =IFERROR(VLOOKUP(D13,'أرصدة المخزن'!$A:$E,3,0),"") | F13: =IFERROR(VLOOKUP(D13,'أرصدة المخزن'!$A:$H,4,0),"") | G13: 24 | H13: إضافة
A14: 8 | B14: 46023 | C14: 210 | D14: 10010027 | E14: =IFERROR(VLOOKUP(D14,'أرصدة المخزن'!$A:$E,3,0),"") | F14: =IFERROR(VLOOKUP(D14,'أرصدة المخزن'!$A:$H,4,0),"") | G14: 1 | H14: إضافة
A15: 9 | B15: 46023 | C15: 210 | D15: 10010067 | E15: =IFERROR(VLOOKUP(D15,'أرصدة المخزن'!$A:$E,3,0),"") | F15: =IFERROR(VLOOKUP(D15,'أرصدة المخزن'!$A:$H,4,0),"") | G15: 89 | H15: إضافة
A16: 10 | B16: 46023 | C16: 210 | D16: 10010100 | E16: =IFERROR(VLOOKUP(D16,'أرصدة المخزن'!$A:$E,3,0),"") | F16: =IFERROR(VLOOKUP(D16,'أرصدة المخزن'!$A:$H,4,0),"") | G16: 10 | H16: إضافة
A17: 11 | B17: 46023 | C17: 210 | D17: 10010025 | E17: =IFERROR(VLOOKUP(D17,'أرصدة المخزن'!$A:$E,3,0),"") | F17: =IFERROR(VLOOKUP(D17,'أرصدة المخزن'!$A:$H,4,0),"") | G17: 12 | H17: إضافة
A18: 12 | B18: 46023 | C18: 210 | D18: 10010145 | E18: =IFERROR(VLOOKUP(D18,'أرصدة المخزن'!$A:$E,3,0),"") | F18: =IFERROR(VLOOKUP(D18,'أرصدة المخزن'!$A:$H,4,0),"") | G18: 3 | H18: إضافة
A19: 13 | B19: 46023 | C19: 210 | D19: 10010136 | E19: =IFERROR(VLOOKUP(D19,'أرصدة المخزن'!$A:$E,3,0),"") | F19: =IFERROR(VLOOKUP(D19,'أرصدة المخزن'!$A:$H,4,0),"") | G19: 1 | H19: إضافة | I19: ليست كاملة 15 متر
A20: 14 | B20: 46023 | C20: 210 | D20: 10010163 | E20: =IFERROR(VLOOKUP(D20,'أرصدة المخزن'!$A:$E,3,0),"") | F20: =IFERROR(VLOOKUP(D20,'أرصدة المخزن'!$A:$H,4,0),"") | G20: 4 | H20: إضافة
A21: 15 | B21: 46023 | C21: 211 | D21: 10010174 | E21: =IFERROR(VLOOKUP(D21,'أرصدة المخزن'!$A:$E,3,0),"") | F21: =IFERROR(VLOOKUP(D21,'أرصدة المخزن'!$A:$H,4,0),"") | G21: 1 | H21: إضافة
A22: 16 | B22: 46023 | C22: 211 | D22: 10010173 | E22: =IFERROR(VLOOKUP(D22,'أرصدة المخزن'!$A:$E,3,0),"") | F22: =IFERROR(VLOOKUP(D22,'أرصدة المخزن'!$A:$H,4,0),"") | G22: 3 | H22: إضافة
A23: 17 | B23: 46023 | C23: 211 | D23: 10020220 | E23: =IFERROR(VLOOKUP(D23,'أرصدة المخزن'!$A:$E,3,0),"") | F23: =IFERROR(VLOOKUP(D23,'أرصدة المخزن'!$A:$H,4,0),"") | G23: 2 | H23: إضافة
A24: 18 | B24: 46023 | C24: 211 | D24: 10080011 | E24: =IFERROR(VLOOKUP(D24,'أرصدة المخزن'!$A:$E,3,0),"") | F24: =IFERROR(VLOOKUP(D24,'أرصدة المخزن'!$A:$H,4,0),"") | G24: 14 | H24: إضافة
A25: 19 | B25: 46023 | C25: 211 | D25: 10080015 | E25: =IFERROR(VLOOKUP(D25,'أرصدة المخزن'!$A:$E,3,0),"") | F25: =IFERROR(VLOOKUP(D25,'أرصدة المخزن'!$A:$H,4,0),"") | G25: 2 | H25: إضافة
A26: 20 | B26: 46023 | C26: 211 | D26: 10010073 | E26: =IFERROR(VLOOKUP(D26,'أرصدة المخزن'!$A:$E,3,0),"") | F26: =IFERROR(VLOOKUP(D26,'أرصدة المخزن'!$A:$H,4,0),"") | G26: 21 | H26: إضافة
A27: 21 | B27: 46023 | C27: 211 | D27: 10160019 | E27: =IFERROR(VLOOKUP(D27,'أرصدة المخزن'!$A:$E,3,0),"") | F27: =IFERROR(VLOOKUP(D27,'أرصدة المخزن'!$A:$H,4,0),"") | G27: 1 | H27: إضافة
A28: 22 | B28: 46023 | C28: 211 | D28: 10170061 | E28: =IFERROR(VLOOKUP(D28,'أرصدة المخزن'!$A:$E,3,0),"") | F28: =IFERROR(VLOOKUP(D28,'أرصدة المخزن'!$A:$H,4,0),"") | G28: 1 | H28: إضافة
A29: 23 | B29: 46023 | C29: 211 | D29: 10080009 | E29: =IFERROR(VLOOKUP(D29,'أرصدة المخزن'!$A:$E,3,0),"") | F29: =IFERROR(VLOOKUP(D29,'أرصدة المخزن'!$A:$H,4,0),"") | G29: 125 | H29: إضافة
A30: 24 | B30: 46023 | C30: 211 | D30: 10010184 | E30: =IFERROR(VLOOKUP(D30,'أرصدة المخزن'!$A:$E,3,0),"") | F30: =IFERROR(VLOOKUP(D30,'أرصدة المخزن'!$A:$H,4,0),"") | G30: 20 | H30: إضافة
A31: 25 | B31: 46023 | C31: 211 | D31: 10040055 | E31: =IFERROR(VLOOKUP(D31,'أرصدة المخزن'!$A:$E,3,0),"") | F31: =IFERROR(VLOOKUP(D31,'أرصدة المخزن'!$A:$H,4,0),"") | G31: 2 | H31: إضافة
A32: 26 | B32: 46023 | C32: 211 | D32: 10010146 | E32: =IFERROR(VLOOKUP(D32,'أرصدة المخزن'!$A:$E,3,0),"") | F32: =IFERROR(VLOOKUP(D32,'أرصدة المخزن'!$A:$H,4,0),"") | G32: 1 | H32: إضافة | I32: ليست كاملة 3متر
A33: 27 | B33: 46023 | C33: 211 | D33: 10010078 | E33: =IFERROR(VLOOKUP(D33,'أرصدة المخزن'!$A:$E,3,0),"") | F33: =IFERROR(VLOOKUP(D33,'أرصدة المخزن'!$A:$H,4,0),"") | G33: 6 | H33: إضافة | I33: وارد شركة لاين لادارة الاصول العقارية
A34: 28 | B34: 46030 | C34: 212 | D34: 10010071 | E34: =IFERROR(VLOOKUP(D34,'أرصدة المخزن'!$A:$E,3,0),"") | F34: =IFERROR(VLOOKUP(D34,'أرصدة المخزن'!$A:$H,4,0),"") | G34: 18 | H34: إضافة | I34: وارد من التشغيل (صيانة) حفلة رأس السنة ببول1
A35: 29 | B35: 46030 | C35: 212 | D35: 10020215 | E35: =IFERROR(VLOOKUP(D35,'أرصدة المخزن'!$A:$E,3,0),"") | F35: =IFERROR(VLOOKUP(D35,'أرصدة المخزن'!$A:$H,4,0),"") | G35: 7 | H35: إضافة | I35: وارد من التشغيل (صيانة) حفلة رأس السنة ببول1
A36: 30 | B36: 46030 | C36: 212 | D36: 10020109 | E36: =IFERROR(VLOOKUP(D36,'أرصدة المخزن'!$A:$E,3,0),"") | F36: =IFERROR(VLOOKUP(D36,'أرصدة المخزن'!$A:$H,4,0),"") | G36: 8 | H36: إضافة | I36: وارد من التشغيل (صيانة) حفلة رأس السنة ببول1
A37: 31 | B37: 46030 | C37: 212 | D37: 10020230 | E37: =IFERROR(VLOOKUP(D37,'أرصدة المخزن'!$A:$E,3,0),"") | F37: =IFERROR(VLOOKUP(D37,'أرصدة المخزن'!$A:$H,4,0),"") | G37: 12 | H37: إضافة | I37: وارد من التشغيل (صيانة) حفلة رأس السنة ببول1
A38: 32 | B38: 46037 | C38: 213 | D38: 10010150 | E38: =IFERROR(VLOOKUP(D38,'أرصدة المخزن'!$A:$E,3,0),"") | F38: =IFERROR(VLOOKUP(D38,'أرصدة المخزن'!$A:$H,4,0),"") | G38: 100 | H38: إضافة | I38: وارد من مخازن بروكس (صيانة)
A39: 33 | B39: 46046 | C39: 214 | D39: 10010129 | E39: =IFERROR(VLOOKUP(D39,'أرصدة المخزن'!$A:$E,3,0),"") | F39: =IFERROR(VLOOKUP(D39,'أرصدة المخزن'!$A:$H,4,0),"") | G39: 5 | H39: إضافة | I39: وارد من التشغيل (صيانة)
A40: 34 | B40: 46046 | C40: 214 | D40: 10160002 | E40: =IFERROR(VLOOKUP(D40,'أرصدة المخزن'!$A:$E,3,0),"") | F40: =IFERROR(VLOOKUP(D40,'أرصدة المخزن'!$A:$H,4,0),"") | G40: 1 | H40: إضافة | I40: وارد اوامر صرف سابقة
A41: 35 | B41: 46046 | C41: 214 | D41: 10010172 | E41: =IFERROR(VLOOKUP(D41,'أرصدة المخزن'!$A:$E,3,0),"") | F41: =IFERROR(VLOOKUP(D41,'أرصدة المخزن'!$A:$H,4,0),"") | G41: 3 | H41: إضافة | I41: وارد من الشغيل صيانة
A42: 36 | B42: 46046 | C42: 214 | D42: 10010166 | E42: =IFERROR(VLOOKUP(D42,'أرصدة المخزن'!$A:$E,3,0),"") | F42: =IFERROR(VLOOKUP(D42,'أرصدة المخزن'!$A:$H,4,0),"") | G42: 5 | H42: إضافة | I42: وارد من الشغيل صيانة
A43: 37 | B43: 46046 | C43: 214 | D43: 10020205 | E43: =IFERROR(VLOOKUP(D43,'أرصدة المخزن'!$A:$E,3,0),"") | F43: =IFERROR(VLOOKUP(D43,'أرصدة المخزن'!$A:$H,4,0),"") | G43: 10 | H43: إضافة | I43: وارد اوامر صرف سابقة
... A54: 48 | B54: 46053 | C54: 215 | D54: 10010119 | E54: =IFERROR(VLOOKUP(D54,'أرصدة المخزن'!$A:$E,3,0),"") | F54: =IFERROR(VLOOKUP(D54,'أرصدة المخزن'!$A:$H,4,0),"") | G54: 5 | H54: إضافة | I54: وارد رضا موسي
...

Sheet الصرف
B4: 🔍 بحث (اسم أو كود): | C4: مفتاح احادي 20 | D4: الصنف المطابق: | E4: =IF(C4="","",IF(ISNUMBER(C4),IFERROR(INDEX('أرصدة المخزن'!$C$4:$C$60000,MATCH(C4,'أرصدة المخزن'!$A$4:$A$60000,0)),"كود غير موجود"),IFERROR(INDEX('أرصدة المخزن'!$C$4:$C$60000,MATCH("*"&TRIM(C4)&"*",'أرصدة المخزن'!$C$4:$C$60000,0)),"صنف غير موجود"))) | F4: =IFERROR(VLOOKUP(E4,'أرصدة المخزن'!$A:$E,3,0),"") | G4: =IF(C4="","",IF(ISNUMBER(C4),IFERROR(INDEX('أرصدة المخزن'!$A$4:$A$60000,MATCH(C4,'أرصدة المخزن'!$A$4:$A$60000,0)),""),IFERROR(INDEX('أرصدة المخزن'!$A$4:$A$60000,MATCH("*"&TRIM(C4)&"*",'أرصدة المخزن'!$C$4:$C$60000,0)),""))) | H4: الوحدة: | I4: =IF(C4="","",IF(ISNUMBER(C4),IFERROR(INDEX('أرصدة المخزن'!$D$4:$D$60000,MATCH(C4,'أرصدة المخزن'!$A$4:$A$60000,0)),""),IFERROR(INDEX('أرصدة المخزن'!$D$4:$D$60000,MATCH("*"&TRIM(C4)&"*",'أرصدة المخزن'!$C$4:$C$60000,0)),""))) | J4: الرصيد المتاح: | K4: =IF(C4="","",IF(ISNUMBER(C4),IFERROR(INDEX('أرصدة المخزن'!$H$4:$H$60000,MATCH(C4,'أرصدة المخزن'!$A$4:$A$60000,0)),0),IFERROR(INDEX('أرصدة المخزن'!$H$4:$H$60000,MATCH("*"&TRIM(C4)&"*",'أرصدة المخزن'!$C$4:$C$60000,0)),0)))
F5: =IFERROR(VLOOKUP(E5,'أرصدة المخزن'!$A:$E,3,0),"") | G5: =IFERROR(VLOOKUP(E5,'أرصدة المخزن'!$A:$H,4,FALSE),"") | K5: =IFERROR(VLOOKUP(E5,'أرصدة المخزن'!$A:$H,8,0),"")
A6: م | B6: التاريخ | C6: الجهه المنصرف إليها | D6: رقم الاذن | E6: كود الصنف | F6: =IFERROR(VLOOKUP(E6,'أرصدة المخزن'!$A:$E,3,0),"") | G6: =IFERROR(VLOOKUP(E6,'أرصدة المخزن'!$A:$H,4,FALSE),"") | H6: الكمية | I6: صرف | J6: ملاحظات | K6: =IFERROR(VLOOKUP(E6,'أرصدة المخزن'!$A:$H,8,0),"")
A7: 1 | B7: 46023 | C7: الصيانة | D7: 826 | E7: 10020089 | F7: =IFERROR(VLOOKUP(E7,'أرصدة المخزن'!$A:$E,3,0),"") | G7: =IFERROR(VLOOKUP(E7,'أرصدة المخزن'!$A:$H,4,FALSE),"") | H7: 4 | I7: صرف | J7: عمارة 371 | K7: =IFERROR(VLOOKUP(E7,'أرصدة المخزن'!$A:$H,8,0),"")
A8: 2 | B8: 46026 | C8: الصيانة | D8: 827 | E8: 10090001 | F8: =IFERROR(VLOOKUP(E8,'أرصدة المخزن'!$A:$E,3,0),"") | G8: =IFERROR(VLOOKUP(E8,'أرصدة المخزن'!$A:$H,4,FALSE),"") | H8: 3 | I8: صرف | J8: عمارات 130-414-394 | K8: =IFERROR(VLOOKUP(E8,'أرصدة المخزن'!$A:$H,8,0),"")
A9: 3 | B9: 46026 | C9: الصيانة | D9: 827 | E9: 10010068 | F9: =IFERROR(VLOOKUP(E9,'أرصدة المخزن'!$A:$E,3,0),"") | G9: =IFERROR(VLOOKUP(E9,'أرصدة المخزن'!$A:$H,4,FALSE),"") | H9: 10 | I9: صرف | J9: عمارة 44 | K9: =IFERROR(VLOOKUP(E9,'أرصدة المخزن'!$A:$H,8,0),"")
A10: 4 | B10: 46026 | C10: الصيانة | D10: 827 | E10: 10170041 | F10: =IFERROR(VLOOKUP(E10,'أرصدة المخزن'!$A:$E,3,0),"") | G10: =IFERROR(VLOOKUP(E10,'أرصدة المخزن'!$A:$H,4,FALSE),"") | H10: 1 | I10: صرف | J10: الموقع العام | K10: =IFERROR(VLOOKUP(E10,'أرصدة المخزن'!$A:$H,8,0),"")
A11: 5 | B11: 46029 | C11: الصيانة | D11: 828 | E11: 10090006 | F11: =IFERROR(VLOOKUP(E11,'أرصدة المخزن'!$A:$E,3,0),"") | G11: =IFERROR(VLOOKUP(E11,'أرصدة المخزن'!$A:$H,4,FALSE),"") | H11: 1 | I11: صرف | J11: بوفيه الادارة | K11: =IFERROR(VLOOKUP(E11,'أرصدة المخزن'!$A:$H,8,0),"")
A12: 6 | B12: 46036 | C12: الصيانة | D12: 829 | E12: 10170065 | F12: =IFERROR(VLOOKUP(E12,'أرصدة المخزن'!$A:$E,3,0),"") | G12: =IFERROR(VLOOKUP(E12,'أرصدة المخزن'!$A:$H,4,FALSE),"") | H12: 2 | I12: صرف | J12: الموقع العام | K12: =IFERROR(VLOOKUP(E12,'أرصدة المخزن'!$A:$H,8,0),"")
A13: 7 | B13: 46036 | C13: الصيانة | D13: 829 | E13: 10010055 | F13: =IFERROR(VLOOKUP(E13,'أرصدة المخزن'!$A:$E,3,0),"") | G13: =IFERROR(VLOOKUP(E13,'أرصدة المخزن'!$A:$H,4,FALSE),"") | H13: 50 | I13: صرف | J13: الموقع العام | K13: =IFERROR(VLOOKUP(E13,'أرصدة المخزن'!$A:$H,8,0),"")
A14: 8 | B14: 46036 | C14: الصيانة | D14: 829 | E14: 10170041 | F14: =IFERROR(VLOOKUP(E14,'أرصدة المخزن'!$A:$E,3,0),"") | G14: =IFERROR(VLOOKUP(E14,'أرصدة المخزن'!$A:$H,4,FALSE),"") | H14: 1 | I14: صرف | J14: الموقع العام | K14: =IFERROR(VLOOKUP(E14,'أرصدة المخزن'!$A:$H,8,0),"")
A15: 9 | B15: 46031 | C15: الصيانة | D15: 830 | E15: 10020227 | F15: =IFERROR(VLOOKUP(E15,'أرصدة المخزن'!$A:$E,3,0),"") | G15: =IFERROR(VLOOKUP(E15,'أرصدة المخزن'!$A:$H,4,FALSE),"") | H15: 4 | I15: صرف | J15: عمارة 1* | K15: =IFERROR(VLOOKUP(E15,'أرصدة المخزن'!$A:$H,8,0),"")
A16: 10 | B16: 46031 | C16: الصيانة | D16: 830 | E16: 10020167 | F16: =IFERROR(VLOOKUP(E16,'أرصدة المخزن'!$A:$E,3,0),"") | G16: =IFERROR(VLOOKUP(E16,'أرصدة المخزن'!$A:$H,4,FALSE),"") | H16: 1 | I16: صرف | J16: عمارة 1* | K16: =IFERROR(VLOOKUP(E16,'أرصدة المخزن'!$A:$H,8,0),"")
A17: 11 | B17: 46033 | C17: الصيانة | D17: 831 | E17: 10170041 | F17: =IFERROR(VLOOKUP(E17,'أرصدة المخزن'!$A:$E,3,0),"") | G17: =IFERROR(VLOOKUP(E17,'أرصدة المخزن'!$A:$H,4,FALSE),"") | H17: 1 | I17: صرف | J17: الموقع العام | K17: =IFERROR(VLOOKUP(E17,'أرصدة المخزن'!$A:$H,8,0),"")
A18: 12 | B18: 46036 | C18: الصيانة | D18: 832 | E18: 10170038 | F18: =IFERROR(VLOOKUP(E18,'أرصدة المخزن'!$A:$E,3,0),"") | G18: =IFERROR(VLOOKUP(E18,'أرصدة المخزن'!$A:$H,4,FALSE),"") | H18: 10 | I18: صرف | J18: الموقع العام | K18: =IFERROR(VLOOKUP(E18,'أرصدة المخزن'!$A:$H,8,0),"")
A19: 13 | B19: 46036 | C19: الصيانة | D19: 832 | E19: 10170056 | F19: =IFERROR(VLOOKUP(E19,'أرصدة المخزن'!$A:$E,3,0),"") | G19: =IFERROR(VLOOKUP(E19,'أرصدة المخزن'!$A:$H,4,FALSE),"") | H19: 3 | I19: صرف | J19: الموقع العام | K19: =IFERROR(VLOOKUP(E19,'أرصدة المخزن'!$A:$H,8,0),"")
A20: 14 | B20: 46035 | C20: الصيانة | D20: 833 | E20: 10160015 | F20: =IFERROR(VLOOKUP(E20,'أرصدة المخزن'!$A:$E,3,0),"") | G20: =IFERROR(VLOOKUP(E20,'أرصدة المخزن'!$A:$H,4,FALSE),"") | H20: 1 | I20: صرف | J20: 0 | K20: =IFERROR(VLOOKUP(E20,'أرصدة المخزن'!$A:$H,8,0),"")
A21: 15 | B21: 46035 | C21: الصيانة | D21: 833 | E21: 10010115 | F21: =IFERROR(VLOOKUP(E21,'أرصدة المخزن'!$A:$E,3,0),"") | G21: =IFERROR(VLOOKUP(E21,'أرصدة المخزن'!$A:$H,4,FALSE),"") | H21: 1 | I21: صرف | J21: 0 | K21: =IFERROR(VLOOKUP(E21,'أرصدة المخزن'!$A:$H,8,0),"")
A22: 16 | B22: 46037 | C22: الصيانة | D22: 834 | E22: 10170001 | F22: =IFERROR(VLOOKUP(E22,'أرصدة المخزن'!$A:$E,3,0),"") | G22: =IFERROR(VLOOKUP(E22,'أرصدة المخزن'!$A:$H,4,FALSE),"") | H22: 100 | I22: صرف | J22: 0 | K22: =IFERROR(VLOOKUP(E22,'أرصدة المخزن'!$A:$H,8,0),"")
A23: 17 | B23: 46041 | C23: الصيانة | D23: 835 | E23: 10010071 | F23: =IFERROR(VLOOKUP(E23,'أرصدة المخزن'!$A:$E,3,0),"") | G23: =IFERROR(VLOOKUP(E23,'أرصدة المخزن'!$A:$H,4,FALSE),"") | H23: 17 | I23: صرف | J23: 0 | K23: =IFERROR(VLOOKUP(E23,'أرصدة المخزن'!$A:$H,8,0),"")
A24: 18 | B24: 46041 | C24: الصيانة | D24: 836 | E24: 10020067 | F24: =IFERROR(VLOOKUP(E24,'أرصدة المخزن'!$A:$E,3,0),"") | G24: =IFERROR(VLOOKUP(E24,'أرصدة المخزن'!$A:$H,4,FALSE),"") | H24: 1 | I24: صرف | J24: 0 | K24: =IFERROR(VLOOKUP(E24,'أرصدة المخزن'!$A:$H,8,0),"")
A25: 19 | B25: 46041 | C25: الصيانة | D25: 836 | E25: 10020162 | F25: =IFERROR(VLOOKUP(E25,'أرصدة المخزن'!$A:$E,3,0),"") | G25: =IFERROR(VLOOKUP(E25,'أرصدة المخزن'!$A:$H,4,FALSE),"") | H25: 1 | I25: صرف | J25: 0 | K25: =IFERROR(VLOOKUP(E25,'أرصدة المخزن'!$A:$H,8,0),"")
A26: 20 | B26: 46042 | C26: الصيانة | D26: 837 | E26: 10170046 | F26: =IFERROR(VLOOKUP(E26,'أرصدة المخزن'!$A:$E,3,0),"") | G26: =IFERROR(VLOOKUP(E26,'أرصدة المخزن'!$A:$H,4,FALSE),"") | H26: 1 | I26: صرف | J26: 0 | K26: =IFERROR(VLOOKUP(E26,'أرصدة المخزن'!$A:$H,8,0),"")
A27: 21 | B27: 46042 | C27: الصيانة | D27: 837 | E27: 10020096 | F27: =IFERROR(VLOOKUP(E27,'أرصدة المخزن'!$A:$E,3,0),"") | G27: =IFERROR(VLOOKUP(E27,'أرصدة المخزن'!$A:$H,4,FALSE),"") | H27: 4 | I27: صرف | J27: تم صرف 1 متر لعمارة 303 | K27: =IFERROR(VLOOKUP(E27,'أرصدة المخزن'!$A:$H,8,0),"")
A28: 22 | B28: 46042 | C28: الصيانة | D28: 838 | E28: 10010119 | F28: =IFERROR(VLOOKUP(E28,'أرصدة المخزن'!$A:$E,3,0),"") | G28: =IFERROR(VLOOKUP(E28,'أرصدة المخزن'!$A:$H,4,FALSE),"") | H28: 1 | I28: صرف | J28: 0 | K28: =IFERROR(VLOOKUP(E28,'أرصدة المخزن'!$A:$H,8,0),"")
A29: 23 | B29: 46042 | C29: الصيانة | D29: 838 | E29: 10010138 | F29: =IFERROR(VLOOKUP(E29,'أرصدة المخزن'!$A:$E,3,0),"") | G29: =IFERROR(VLOOKUP(E29,'أرصدة المخزن'!$A:$H,4,FALSE),"") | H29: 1 | I29: صرف | J29: 0 | K29: =IFERROR(VLOOKUP(E29,'أرصدة المخزن'!$A:$H,8,0),"")
A30: 24 | B30: 46042 | C30: الصيانة | D30: 838 | E30: 10170065 | F30: =IFERROR(VLOOKUP(E30,'أرصدة المخزن'!$A:$E,3,0),"") | G30: =IFERROR(VLOOKUP(E30,'أرصدة المخزن'!$A:$H,4,FALSE),"") | H30: 1 | I30: صرف | J30: 0 | K30: =IFERROR(VLOOKUP(E30,'أرصدة المخزن'!$A:$H,8,0),"")
A31: 25 | B31: 46042 | C31: الصيانة | D31: 839 | E31: 10020167 | F31: =IFERROR(VLOOKUP(E31,'أرصدة المخزن'!$A:$E,3,0),"") | G31: =IFERROR(VLOOKUP(E31,'أرصدة المخزن'!$A:$H,4,FALSE),"") | H31: 2 | I31: صرف | J31: 0 | K31: =IFERROR(VLOOKUP(E31,'أرصدة المخزن'!$A:$H,8,0),"")
A32: 26 | B32: 46042 | C32: الصيانة | D32: 839 | E32: 10020159 | F32: =IFERROR(VLOOKUP(E32,'أرصدة المخزن'!$A:$E,3,0),"") | G32: =IFERROR(VLOOKUP(E32,'أرصدة المخزن'!$A:$H,4,FALSE),"") | H32: 2 | I32: صرف | J32: 0 | K32: =IFERROR(VLOOKUP(E32,'أرصدة المخزن'!$A:$H,8,0),"")
A33: 27 | B33: 46042 | C33: الصيانة | D33: 839 | E33: 10020155 | F33: =IFERROR(VLOOKUP(E33,'أرصدة المخزن'!$A:$E,3,0),"") | G33: =IFERROR(VLOOKUP(E33,'أرصدة المخزن'!$A:$H,4,FALSE),"") | H33: 1 | I33: صرف | J33: 0 | K33: =IFERROR(VLOOKUP(E33,'أرصدة المخزن'!$A:$H,8,0),"")
A34: 28 | B34: 46042 | C34: الصيانة | D34: 839 | E34: 10020103 | F34: =IFERROR(VLOOKUP(E34,'أرصدة المخزن'!$A:$E,3,0),"") | G34: =IFERROR(VLOOKUP(E34,'أرصدة المخزن'!$A:$H,4,FALSE),"") | H34: 1 | I34: صرف | J34: 0 | K34: =IFERROR(VLOOKUP(E34,'أرصدة المخزن'!$A:$H,8,0),"")
A35: 29 | B35: 46044 | C35: الصيانة | D35: 840 | E35: 10010058 | F35: =IFERROR(VLOOKUP(E35,'أرصدة المخزن'!$A:$E,3,0),"") | G35: =IFERROR(VLOOKUP(E35,'أرصدة المخزن'!$A:$H,4,FALSE),"") | H35: 50 | I35: صرف | J35: 0 | K35: =IFERROR(VLOOKUP(E35,'أرصدة المخزن'!$A:$H,8,0),"")
A36: 30 | B36: 46045 | C36: الصيانة | D36: 841 | E36: 10020166 | F36: =IFERROR(VLOOKUP(E36,'أرصدة المخزن'!$A:$E,3,0),"") | G36: =IFERROR(VLOOKUP(E36,'أرصدة المخزن'!$A:$H,4,FALSE),"") | H36: 1 | I36: صرف | J36: 0 | K36: =IFERROR(VLOOKUP(E36,'أرصدة المخزن'!$A:$H,8,0),"")
A37: 31 | B37: 46046 | C37: الصيانة | D37: 842 | E37: 10010005 | F37: =IFERROR(VLOOKUP(E37,'أرصدة المخزن'!$A:$E,3,0),"") | G37: =IFERROR(VLOOKUP(E37,'أرصدة المخزن'!$A:$H,4,FALSE),"") | H37: 20 | I37: صرف | J37: 0 | K37: =IFERROR(VLOOKUP(E37,'أرصدة المخزن'!$A:$H,8,0),"")
A38: 32 | B38: 46046 | C38: النظافة | D38: 842 | E38: 10010187 | F38: =IFERROR(VLOOKUP(E38,'أرصدة المخزن'!$A:$E,3,0),"") | G38: =IFERROR(VLOOKUP(E38,'أرصدة المخزن'!$A:$H,4,FALSE),"") | H38: 1 | I38: صرف | J38: 0 | K38: =IFERROR(VLOOKUP(E38,'أرصدة المخزن'!$A:$H,8,0),"")
A39: 33 | B39: 46046 | C39: الصيانة | D39: 843 | E39: 10050002 | F39: =IFERROR(VLOOKUP(E39,'أرصدة المخزن'!$A:$E,3,0),"") | G39: =IFERROR(VLOOKUP(E39,'أرصدة المخزن'!$A:$H,4,FALSE),"") | H39: 3 | I39: صرف | J39: 0 | K39: =IFERROR(VLOOKUP(E39,'أرصدة المخزن'!$A:$H,8,0),"")
... A59: 53 | B59: 46058 | C59: الصيانة | D59: 858 | E59: 10170001 | F59: =IFERROR(VLOOKUP(E59,'أرصدة المخزن'!$A:$E,3,0),"") | G59: =IFERROR(VLOOKUP(E59,'أرصدة المخزن'!$A:$H,4,FALSE),"") | H59: 300 | I59: صرف | J59: 0 | K59: =IFERROR(VLOOKUP(E59,'أرصدة المخزن'!$A:$H,8,0),"")
A60: 54 | B60: 46058 | C60: الصيانة | D60: 858 | E60: 10010150 | F60: =IFERROR(VLOOKUP(E60,'أرصدة المخزن'!$A:$E,3,0),"") | G60: =IFERROR(VLOOKUP(E60,'أرصدة المخزن'!$A:$H,4,FALSE),"") | H60: 1 | I60: صرف | K60: =IFERROR(VLOOKUP(E60,'أرصدة المخزن'!$A:$H,8,0),"")
A61: 55 | B61: 46058 | C61: الري بلوم | D61: 859 | E61: 10030031 | F61: =IFERROR(VLOOKUP(E61,'أرصدة المخزن'!$A:$E,3,0),"") | G61: =IFERROR(VLOOKUP(E61,'أرصدة المخزن'!$A:$H,4,FALSE),"") | H61: 2 | I61: صرف | J61: 0 | K61: =IFERROR(VLOOKUP(E61,'أرصدة المخزن'!$A:$H,8,0),"")
A62: 56 | B62: 46058 | C62: الري سلطان | D62: 860 | E62: 10030037 | F62: =IFERROR(VLOOKUP(E62,'أرصدة المخزن'!$A:$E,3,0),"") | G62: =IFERROR(VLOOKUP(E62,'أرصدة المخزن'!$A:$H,4,FALSE),"") | H62: 2 | I62: صرف | J62: 0 | K62: =IFERROR(VLOOKUP(E62,'أرصدة المخزن'!$A:$H,8,0),"")
...

Sheet كارت الصنف
A2: كارت الصنف
A3: كود الصنف | B3: 10010109 | C3: =VLOOKUP(B3,'أرصدة المخزن'!$A:$E,3,0) | D3: الرصيــــــــــــــــــــــــد | E3: =SUBTOTAL(9,F6:F371)+E5 | F3: بدون حركة
A4: الشهر | B4: التاريخ | C4: الإضافة | D4: الصرف | E4: رصيد أخر اليوم
A5: رصيد اول المــــــــــــــــــــــــــــــــــــــــــــــــــــــــــــــــــــــــــــدة | E5: =VLOOKUP(B3,'أرصدة المخزن'!A:H,5,0)
A6: =TEXT(B6,"mmmm") | B6: 46023 | C6: =SUMIFS(الاضافة!$G:$G,الاضافة!$E:$E,$C$3,الاضافة!$B:$B,B6) | D6: =SUMIFS(الصرف!$H$7:$H$60000,الصرف!$F$7:$F$60000,$C$3,الصرف!$B$7:$B$60000,B6) | E6: =E5+C6-D6 | F6: =C6-D6
A7: =TEXT(B7,"mmmm") | B7: 46024 | C7: =SUMIFS(الاضافة!$G:$G,الاضافة!$E:$E,$C$3,الاضافة!$B:$B,B7) | D7: =SUMIFS(الصرف!$H$7:$H$60000,الصرف!$F$7:$F$60000,$C$3,الصرف!$B$7:$B$60000,B7) | E7: =E6+C7-D7 | F7: =C7-D7
A8: =TEXT(B8,"mmmm") | B8: 46025 | C8: =SUMIFS(الاضافة!$G:$G,الاضافة!$E:$E,$C$3,الاضافة!$B:$B,B8) | D8: =SUMIFS(الصرف!$H$7:$H$60000,الصرف!$F$7:$F$60000,$C$3,الصرف!$B$7:$B$60000,B8) | E8: =E7+C8-D8 | F8: =C8-D8
A9: =TEXT(B9,"mmmm") | B9: 46026 | C9: =SUMIFS(الاضافة!$G:$G,الاضافة!$E:$E,$C$3,الاضافة!$B:$B,B9) | D9: =SUMIFS(الصرف!$H$7:$H$60000,الصرف!$F$7:$F$60000,$C$3,الصرف!$B$7:$B$60000,B9) | E9: =E8+C9-D9 | F9: =C9-D9
A10: =TEXT(B10,"mmmm") | B10: 46027 | C10: =SUMIFS(الاضافة!$G:$G,الاضافة!$E:$E,$C$3,الاضافة!$B:$B,B10) | D10: =SUMIFS(الصرف!$H$7:$H$60000,الصرف!$F$7:$F$60000,$C$3,الصرف!$B$7:$B$60000,B10) | E10: =E9+C10-D10 | F10: =C10-D10
A11: =TEXT(B11,"mmmm") | B11: 46028 | C11: =SUMIFS(الاضافة!$G:$G,الاضافة!$E:$E,$C$3,الاضافة!$B:$B,B11) | D11: =SUMIFS(الصرف!$H$7:$H$60000,الصرف!$F$7:$F$60000,$C$3,الصرف!$B$7:$B$60000,B11) | E11: =E10+C11-D11 | F11: =C11-D11
A12: =TEXT(B12,"mmmm") | B12: 46029 | C12: =SUMIFS(الاضافة!$G:$G,الاضافة!$E:$E,$C$3,الاضافة!$B:$B,B12) | D12: =SUMIFS(الصرف!$H$7:$H$60000,الصرف!$F$7:$F$60000,$C$3,الصرف!$B$7:$B$60000,B12) | E12: =E11+C12-D12 | F12: =C12-D12
A13: =TEXT(B13,"mmmm") | B13: 46030 | C13: =SUMIFS(الاضافة!$G:$G,الاضافة!$E:$E,$C$3,الاضافة!$B:$B,B13) | D13: =SUMIFS(الصرف!$H$7:$H$60000,الصرف!$F$7:$F$60000,$C$3,الصرف!$B$7:$B$60000,B13) | E13: =E12+C13-D13 | F13: =C13-D13
A14: =TEXT(B14,"mmmm") | B14: 46031 | C14: =SUMIFS(الاضافة!$G:$G,الاضافة!$E:$E,$C$3,الاضافة!$B:$B,B14) | D14: =SUMIFS(الصرف!$H$7:$H$60000,الصرف!$F$7:$F$60000,$C$3,الصرف!$B$7:$B$60000,B14) | E14: =E13+C14-D14 | F14: =C14-D14
A15: =TEXT(B15,"mmmm") | B15: 46032 | C15: =SUMIFS(الاضافة!$G:$G,الاضافة!$E:$E,$C$3,الاضافة!$B:$B,B15) | D15: =SUMIFS(الصرف!$H$7:$H$60000,الصرف!$F$7:$F$60000,$C$3,الصرف!$B$7:$B$60000,B15) | E15: =E14+C15-D15 | F15: =C15-D15
A16: =TEXT(B16,"mmmm") | B16: 46033 | C16: =SUMIFS(الاضافة!$G:$G,الاضافة!$E:$E,$C$3,الاضافة!$B:$B,B16) | D16: =SUMIFS(الصرف!$H$7:$H$60000,الصرف!$F$7:$F$60000,$C$3,الصرف!$B$7:$B$60000,B16) | E16: =E15+C16-D16 | F16: =C16-D16
A17: =TEXT(B17,"mmmm") | B17: 46034 | C17: =SUMIFS(الاضافة!$G:$G,الاضافة!$E:$E,$C$3,الاضافة!$B:$B,B17) | D17: =SUMIFS(الصرف!$H$7:$H$60000,الصرف!$F$7:$F$60000,$C$3,الصرف!$B$7:$B$60000,B17) | E17: =E16+C17-D17 | F17: =C17-D17
... A370: =TEXT(B370,"mmmm") | B370: 46387 | C370: =SUMIFS(الاضافة!$G:$G,الاضافة!$E:$E,$C$3,الاضافة!$B:$B,B370) | D370: =SUMIFS(الصرف!$H$7:$H$60000,الصرف!$F$7:$F$60000,$C$3,الصرف!$B$7:$B$60000,B370) | E370: =E369+C370-D370 | F370: =C370-D370
A371: =TEXT(B371,"mmmm") | B371: 46388 | C371: =SUMIFS(الاضافة!$G:$G,الاضافة!$E:$E,$C$3,الاضافة!$B:$B,B371) | D371: =SUMIFS(الصرف!$H$7:$H$60000,الصرف!$F$7:$F$60000,$C$3,الصرف!$B$7:$B$60000,B371) | E371: =E369+C371-D371 | F371: =C371-D371

Sheet أصناف بدون حركة
A1: م | B1: القسم | C1: الكود القديم | D1: الكود الجديد | E1: اسم الصنف | F1: الوحدة | G1: رصيد أول المدة | H1: إجمالي الوارد | I1: إجمالي المنصرف | J1: الرصيد الحالي | K1: حالة الصنف
A2: 1 | B2: أدوات كهربائية | C2: 1001 | D2: 10010031 | E2: مفتاح قاطع تيار ( بلمبات إشارة np تركي | F2: عدد | G2: 0 | H2: 0 | I2: 0 | J2: 0 | K2: صنف راكد مسجل بدون حركة
A3: 2 | B3: أدوات كهربائية | C3: 1015 | D3: 10010032 | E3: مفتاح ديفيتر | F3: عدد | G3: 0 | H3: 0 | I3: 0 | J3: 0 | K3: صنف راكد مسجل بدون حركة
A4: 3 | B4: أدوات كهربائية | C4: 1017 | D4: 10010178 | E4: كوسية 50 مم | F4: عدد | G4: 0 | H4: 0 | I4: 0 | J4: 0 | K4: صنف راكد مسجل بدون حركة
A5: 4 | B5: أدوات كهربائية | C5: 1019 | D5: 100289 | E5: مسمار سن صاج 4 سم | F5: علبة | G5: 0 | H5: 0 | I5: 0 | J5: 0 | K5: صنف راكد مسجل بدون حركة
A6: 5 | B6: أدوات كهربائية | C6: 1030 | D6: 10010033 | E6: مفتاح دفتير بتشينو | F6: عدد | G6: 0 | H6: 0 | I6: 0 | J6: 0 | K6: صنف راكد مسجل بدون حركة
A7: 6 | B7: أدوات كهربائية | C7: 1032 | D7: 10170085 | E7: كيس افيز بلاستيك صفير | F7: عدد | G7: 0 | H7: 0 | I7: 0 | J7: 0 | K7: صنف راكد مسجل بدون حركة
A8: 7 | B8: أدوات كهربائية | C8: 1050 | D8: 100292 | E8: مبرد | F8: كيلو | G8: 0 | H8: 0 | I8: 0 | J8: 0 | K8: صنف راكد مسجل بدون حركة
A9: 8 | B9: أدوات كهربائية | C9: 1051 | D9: 10170051 | E9: سيليكون عضم | F9: عدد | G9: 0 | H9: 0 | I9: 0 | J9: 0 | K9: صنف راكد مسجل بدون حركة
A10: 9 | B10: أدوات كهربائية | C10: 1054 | D10: 10010098 | E10: شلباية علي التيار 200 وات | F10: عدد | G10: 0 | H10: 0 | I10: 0 | J10: 0 | K10: صنف راكد مسجل بدون حركة
A11: 10 | B11: أدوات كهربائية | C11: 1057 | D11: 10170086 | E11: اصدير 750 | F11: بكرة | G11: 0 | H11: 0 | I11: 0 | J11: 0 | K11: صنف راكد مسجل بدون حركة
A12: 11 | B12: أدوات كهربائية | C12: 1059 | D12: 10010053 | E12: تايمر ABB | F12: عدد | G12: 0 | H12: 0 | I12: 0 | J12: 0 | K12: صنف راكد مسجل بدون حركة
A13: 12 | B13: أدوات كهربائية | C13: 1067 | D13: 10010099 | E13: شلباية عمود نور بالترنس | G13: 0 | H13: 0 | I13: 0 | J13: 0 | K13: صنف راكد مسجل بدون حركة
A14: 13 | B14: أدوات كهربائية | C14: 1078 | D14: 10010179 | E14: سرافيل 16 م | F14: عدد | G14: 0 | H14: 0 | I14: 0 | J14: 0 | K14: صنف راكد مسجل بدون حركة
A15: 14 | B15: أدوات كهربائية | C15: 1079 | D15: 10010148 | E15: غطاء كابل 16 م | F15: عدد | G15: 0 | H15: 0 | I15: 0 | J15: 0 | K15: صنف راكد مسجل بدون حركة
A16: 15 | B16: أدوات كهربائية | C16: 1081 | D16: 10010149 | E16: كابل مسلح 25 م 4 طرف | F16: متر | G16: 0 | H16: 0 | I16: 0 | J16: 0 | K16: صنف راكد مسجل بدون حركة
A17: 16 | B17: أدوات كهربائية | C17: 1082 | D17: 10010180 | E17: سرافيل 25 م | F17: عدد | G17: 0 | H17: 0 | I17: 0 | J17: 0 | K17: صنف راكد مسجل بدون حركة
A18: 17 | B18: أدوات كهربائية | C18: 1094 | D18: 10010034 | E18: بريزة وتر بروف | F18: عدد | G18: 0 | H18: 0 | I18: 0 | J18: 0 | K18: صنف راكد مسجل بدون حركة
A19: 18 | B19: أدوات كهربائية | C19: 1097 | D19: 10010054 | E19: بور صبلاي | F19: عدد | G19: 0 | H19: 0 | I19: 0 | J19: 0 | K19: صنف راكد مسجل بدون حركة
A20: 19 | B20: أدوات وسباكة وشبكات | C20: 1287 | D20: 10020238 | E20: مادة معالجة الشقوق فيكاريب 2سم | F20: عدد | G20: 0 | H20: 0 | I20: 0 | J20: 0 | K20: صنف راكد مسجل بدون حركة
A21: 20 | B21: أدوات وسباكة وشبكات | C21: 1296 | D21: 10020220 | E21: جلبة 20 ملي بولي | F21: عدد | G21: 0 | H21: 0 | I21: 0 | J21: 0 | K21: صنف راكد مسجل بدون حركة
A22: 21 | B22: أدوات وسباكة وشبكات | C22: 1319 | D22: 10020245 | E22: لقمة 4/3 ابي تي مكوة اللحام | F22: عدد | G22: 0 | H22: 0 | I22: 0 | J22: 0 | K22: صنف راكد مسجل بدون حركة
A23: 22 | B23: أدوات وسباكة وشبكات | C23: 1326 | D23: 10170011 | E23: كوع 110 كومر 16 بار | F23: عدد | G23: 0 | H23: 0 | I23: 0 | J23: 0 | K23: صنف راكد مسجل بدون حركة
A24: 23 | B24: أدوات وسباكة وشبكات | C24: 1327 | D24: 10020271 | E24: علبة مطهرمواسير صغير | F24: علبة | G24: 0 | H24: 0 | I24: 0 | J24: 0 | K24: صنف راكد مسجل بدون حركة
A25: 24 | B25: أدوات وسباكة وشبكات | C25: 1361 | D25: 10020263 | E25: جوان 4 حيبوتي ظهر | F25: عدد | G25: 0 | H25: 0 | I25: 0 | J25: 0 | K25: صنف راكد مسجل بدون حركة
... A46: 45 | B46: أدوات عامة | C46: 2067 | D46: 10080024 | E46: حجاري بدون يد | F46: عدد | G46: 0 | H46: 0 | I46: 0 | J46: 0 | K46: صنف راكد مسجل بدون حركة
A47: 46 | B47: أدوات عامة | C47: 2092 | D47: 107135 | E47: باكت بنط 3.5مم(10 بنط ) | G47: 0 | H47: 0 | I47: 0 | J47: 0 | K47: صنف راكد مسجل بدون حركة
A48: 47 | B48: أدوات عامة | C48: 2093 | D48: 107136 | E48: باكت بنط 4مم(10 بنط ) | G48: 0 | H48: 0 | I48: 0 | J48: 0 | K48: صنف راكد مسجل بدون حركة
A49: 48 | B49: أدوات عامة | C49: 2094 | D49: 107137 | E49: سوستة ايطالي 25 متر بلاستيك | G49: 0 | H49: 0 | I49: 0 | J49: 0 | K49: صنف راكد مسجل بدون حركة
A50: 49 | B50: أدوات عامة | C50: 2095 | D50: 107138 | E50: ماكينة برشام | G50: 0 | H50: 0 | I50: 0 | J50: 0 | K50: صنف راكد مسجل بدون حركة
A51: 50 | B51: أدوات عامة | C51: 2097 | D51: 107139 | E51: الفونية لحام | G51: 0 | H51: 0 | I51: 0 | J51: 0 | K51: صنف راكد مسجل بدون حركة
A52: 51 | B52: أدوات عامة | C52: 2098 | D52: 10170088 | E52: شريط تحذير | G52: 0 | H52: 0 | I52: 0 | J52: 0 | K52: صنف راكد مسجل بدون حركة
A53: 52 | B53: أدوات عامة | C53: 2099 | D53: 107141 | E53: بنطة مغناطيس صليبة | G53: 0 | H53: 0 | I53: 0 | J53: 0 | K53: صنف راكد مسجل بدون حركة
A54: 53 | B54: أدوات عامة | C54: 2100 | D54: 107142 | E54: مفتاح بلدي 13 | G54: 0 | H54: 0 | I54: 0 | J54: 0 | K54: صنف راكد مسجل بدون حركة
A55: 54 | B55: أدوات عامة | C55: 2101 | D55: 107143 | E55: مفتاح بلدي 17 | G55: 0 | H55: 0 | I55: 0 | J55: 0 | K55: صنف راكد مسجل بدون حركة
A56: 55 | B56: أدوات سيكوريت | C56: 1603 | D56: 10090007 | E56: عود سيلنج | F56: عدد | G56: 0 | H56: 0 | I56: 0 | J56: 0 | K56: صنف راكد مسجل بدون حركة
A57: 56 | B57: أدوات سيكوريت | C57: 1604 | D57: 108111 | E57: لاصق رندر | F57: عدد | G57: 0 | H57: 0 | I57: 0 | J57: 0 | K57: صنف راكد مسجل بدون حركة
A58: 57 | B58: أدوات سيكوريت | C58: 1605 | D58: 108112 | E58: مسمار جبس 3 سم | F58: علبة | G58: 0 | H58: 0 | I58: 0 | J58: 0 | K58: صنف راكد مسجل بدون حركة
A59: 58 | B59: أدوات سيكوريت | C59: 1606 | D59: 108113 | E59: بنطة 5 فدية | F59: عدد | G59: 0 | H59: 0 | I59: 0 | J59: 0 | K59: صنف راكد مسجل بدون حركة
A60: 59 | B60: أدوات سيكوريت | C60: 1607 | D60: 108114 | E60: جزلة شحم | F60: عدد | G60: 0 | H60: 0 | I60: 0 | J60: 0 | K60: صنف راكد مسجل بدون حركة
...

Sheet الوارد من التشغيل (مستعمل)
A1: سجل الوارد من التشغيل والمهمات المستعملة (Operational Returns Ledger) - The Calm WMS
A2: شركة ذا كالم لإدارة المرافق والخدمات | موقع ستون رزيدنس - التجمع الخامس | قسم إدارة المخزون الفني
B3: إجمالي الحركات المستلمة | E3: صالح لإعادة الاستخدام | H3: يحتاج فحص وصيانة | K3: كهنة وسكراب تالف
B4: =COUNTA(C7:C500) | E4: =COUNTIF(J7:J500, "صالح للاستخدام") | H4: =COUNTIF(J7:J500, "يحتاج صيانة") | K4: =COUNTIF(J7:J500, "كهنة سكراب")
A6: م | B6: التاريخ | C6: رقم إذن المرتجع | D6: الفني / الجهة المسلمة | E6: القسم التابع له | F6: كود الصنف المرجعي | G6: اسم الصنف المستعمل | H6: الوحدة | I6: الكمية المستلمة | J6: الحالة الفنية | K6: مكان التخزين الميداني | L6: رقم أمر الشغل / المحضر | M6: الملاحظات والبيان
A7: 1 | B7: 46280 | C7: RET-2026-001 | E7: أدوات سباكة | F7: 10020156 | G7: محبس 6 بوصة بولندي (مستعمل بحالة جيدة) | H7: عدد | I7: 1 | J7: صالح للاستخدام | K7: مستودع الرجيع - رف B1 | L7: WO-4412 | M7: تم فكه من عمارة 120 بعد إحلال محبس أكبر، صالح تماماً
A8: 2 | B8: 46285 | C8: RET-2026-002 | E8: أدوات كهربائية | F8: 10010099 | G8: شلباية عمود نور بالترنس (تحتاج صيانة) | H8: عدد | I8: 2 | J8: يحتاج صيانة | K8: ورشة صيانة الكهرباء | L8: WO-4480 | M8: مرتجع من أعمدة المنطقة 4، بحاجة لتغيير الترنس الداخلي
A9: 3 | B9: 46293 | C9: RET-2026-003 | E9: أدوات خامات الري | F9: 10030002 | G9: حربة تثبيت 20 سم مكسورة (كهنة) | H9: عدد | I9: 15 | J9: كهنة سكراب | K9: ساحة تخريد المهمات | L9: WO-4530 | M9: تالفة أثناء أعمال حفر خط الري الرئيسي، غير صالحة
A10: 4
A11: 5
A12: 6
A13: 7
A14: 8
A15: 9
A16: 10
A17: 11
A18: 12
A19: 13
A20: 14
A21: 15
... A100: 94

Sheet الأذون الملغية
A1: سجل الأذون الملغية والمستبعدة من الحركة المخزنية - The Calm WMS
A2: ملاحظة: تم تخصيص الكود الصوري 9999 لجميع الأذون الملغية مع الإبقاء على أرقامها بالدفاتر الأصلية لمنع أي فجوات رقمية
A4: أولاً: أذون الإضافة الملغية (إجمالي 8 أذون)
A5: م | B5: التاريخ | C5: رقم إذن الإضافة | D5: الكود المخصص | E5: اسم الصنف | F5: الكمية | G5: نوع الحركة | H5: حالة الإلغاء والبيان
A6: 540 | B6: 46143 | C6: 292 | D6: 9999 | E6: إذن ملغي | F6: 0 | G6: إضافة | H6: إذن ملغي - مؤرشف بالسجل المستقل
A7: 559 | B7: 46143 | C7: 294 | D7: 9999 | E7: إذن ملغي | F7: 0 | G7: إضافة | H7: إذن ملغي - مؤرشف بالسجل المستقل
A8: 595 | B8: 46143 | C8: 296 | D8: 9999 | E8: إذن ملغي | F8: 0 | G8: إضافة | H8: إذن ملغي - مؤرشف بالسجل المستقل
A9: 599 | B9: 46143 | C9: 296 | D9: 9999 | E9: إذن ملغي | F9: 0 | G9: إضافة | H9: إذن ملغي - مؤرشف بالسجل المستقل
A10: 616 | B10: 46143 | C10: 298 | D10: 9999 | E10: إذن ملغي | F10: 0 | G10: إضافة | H10: إذن ملغي - مؤرشف بالسجل المستقل
A11: 731 | B11: 46156 | C11: 17 | D11: 9999 | E11: إذن ملغي | F11: 0 | G11: إضافة | H11: إذن ملغي - مؤرشف بالسجل المستقل
A12: 781 | B12: 46167 | C12: 34 | D12: 9999 | E12: إذن ملغي | F12: 0 | G12: إضافة | H12: إذن ملغي - مؤرشف بالسجل المستقل
A13: 784 | B13: 46167 | C13: 34 | D13: 9999 | E13: إذن ملغي | F13: 0 | G13: إضافة | H13: إذن ملغي - مؤرشف بالسجل المستقل
A16: ثانياً: أذون الصرف الملغية (إجمالي 15 إذناً)
A17: م | B17: التاريخ | C17: الجهة المسجلة | D17: رقم إذن الصرف | E17: الكود المخصص | F17: اسم الصنف | G17: الكمية | H17: نوع الحركة | I17: حالة الإلغاء والبيان
A18: 182 | B18: 46081 | C18: - | D18: 909 | E18: 9999 | F18: إذن ملغي | G18: 0 | H18: صرف | I18: إذن ملغي - مؤرشف بالسجل المستقل
A19: 417 | B19: 46117 | C19: - | D19: 999 | E19: 9999 | F19: إذن ملغي | G19: 0 | H19: صرف | I19: إذن ملغي - مؤرشف بالسجل المستقل
A20: 418 | B20: 46117 | C20: - | D20: 1000 | E20: 9999 | F20: إذن ملغي | G20: 0 | H20: صرف | I20: إذن ملغي - مؤرشف بالسجل المستقل
A21: 808 | B21: 46146 | C21: المسطحات المائية | D21: 1141 | E21: 9999 | F21: إذن ملغي | G21: 0 | H21: صرف | I21: إذن ملغي - مؤرشف بالسجل المستقل
A22: 827 | B22: 46146 | C22: المسطحات المائية | D22: 1146 | E22: 9999 | F22: إذن ملغي | G22: 0 | H22: صرف | I22: إذن ملغي - مؤرشف بالسجل المستقل
A23: 863 | B23: 46146 | C23: المسطحات المائية | D23: 5 | E23: 9999 | F23: إذن ملغي | G23: 0 | H23: صرف | I23: إذن ملغي - مؤرشف بالسجل المستقل
A24: 867 | B24: 46146 | C24: المسطحات المائية | D24: 6 | E24: 9999 | F24: إذن ملغي | G24: 0 | H24: صرف | I24: إذن ملغي - مؤرشف بالسجل المستقل
A25: 885 | B25: 46146 | C25: المسطحات المائية | D25: 11 | E25: 9999 | F25: إذن ملغي | G25: 0 | H25: صرف | I25: إذن ملغي - مؤرشف بالسجل المستقل
A26: 926 | C26: - | D26: 30 | E26: 9999 | F26: إذن ملغي | G26: 0 | H26: صرف | I26: إذن ملغي - مؤرشف بالسجل المستقل
A27: 927 | C27: - | D27: 31 | E27: 9999 | F27: إذن ملغي | G27: 0 | H27: صرف | I27: إذن ملغي - مؤرشف بالسجل المستقل
A28: 1121 | B28: 46167 | C28: الري بلوم | D28: 100 | E28: 9999 | F28: إذن ملغي | G28: 0 | H28: صرف | I28: إذن ملغي - مؤرشف بالسجل المستقل
A29: 1124 | B29: 46167 | C29: الري بلوم | D29: 100 | E29: 9999 | F29: إذن ملغي | G29: 0 | H29: صرف | I29: إذن ملغي - مؤرشف بالسجل المستقل
A30: 1434 | B30: 46196 | C30: الصيانة لاين | D30: 234 | E30: 9999 | F30: إذن ملغي | G30: 0 | H30: صرف | I30: إذن ملغي - مؤرشف بالسجل المستقل
A31: 1435 | B31: 46196 | C31: الصيانة لاين | D31: 234 | E31: 9999 | F31: إذن ملغي | G31: 0 | H31: صرف | I31: إذن ملغي - مؤرشف بالسجل المستقل
A32: 2479 | B32: 46280 | C32: النظافة كايرو | D32: 691 | E32: 9999 | F32: إذن ملغي | G32: 0 | H32: صرف | I32: إذن ملغي - مؤرشف بالسجل المستقل
